Loading intel/2024.1.0
  Loading requirement: oclfpga/2024.1.0 compiler-rt/2024.1.0 tbb/2021.12
    compiler/2024.1.0 mpi/2021.12 mkl/2024.1
Traceback (most recent call last):
  File "/home/t/t541/.local/lib/python3.9/site-packages/llvmlite/binding/ffi.py", line 136, in __getattr__
Traceback (most recent call last):
  File "/home/t/t541/.local/lib/python3.9/site-packages/llvmlite/binding/ffi.py", line 136, in __getattr__
    return self._fntab[name]
KeyError: 'LLVMPY_AddSymbol'

During handling of the above exception, another exception occurred:

Traceback (most recent call last):
  File "/home/t/t541/.local/lib/python3.9/site-packages/llvmlite/binding/ffi.py", line 117, in _load_lib
    return self._fntab[name]
KeyError: 'LLVMPY_AddSymbol'

During handling of the above exception, another exception occurred:

Traceback (most recent call last):
  File "/home/t/t541/.local/lib/python3.9/site-packages/llvmlite/binding/ffi.py", line 117, in _load_lib
    self._lib_handle = ctypes.CDLL(str(lib_path))
  File "/ssd/t/t541/.src/anaconda3/envs/lbs_env/lib/python3.9/ctypes/__init__.py", line 382, in __init__
    self._lib_handle = ctypes.CDLL(str(lib_path))
  File "/ssd/t/t541/.src/anaconda3/envs/lbs_env/lib/python3.9/ctypes/__init__.py", line 382, in __init__
    self._handle = _dlopen(self._name, mode)
OSError: /home/t/t541/.local/lib/python3.9/site-packages/llvmlite/binding/libllvmlite.so: cannot open shared object file: No such file or directory
    self._handle = _dlopen(self._name, mode)
OSError: /home/t/t541/.local/lib/python3.9/site-packages/llvmlite/binding/libllvmlite.so: cannot open shared object file: No such file or directory

The above exception was the direct cause of the following exception:

Traceback (most recent call last):
  File "/data/t/t541/jss3_tools/example/RURI/get_hitmap_parallel_ruri.py", line 1, in <module>

The above exception was the direct cause of the following exception:

Traceback (most recent call last):
  File "/data/t/t541/jss3_tools/example/RURI/get_hitmap_parallel_ruri.py", line 1, in <module>
    import litebird_sim as lbs
  File "/data/t/t541/litebird/lbsim_branches/litebird_sim/litebird_sim/__init__.py", line 5, in <module>
    import litebird_sim as lbs
  File "/data/t/t541/litebird/lbsim_branches/litebird_sim/litebird_sim/__init__.py", line 5, in <module>
    import numba
  File "/home/t/t541/.local/lib/python3.9/site-packages/numba/__init__.py", line 73, in <module>
    import numba
  File "/home/t/t541/.local/lib/python3.9/site-packages/numba/__init__.py", line 73, in <module>
    from numba.core import config
  File "/home/t/t541/.local/lib/python3.9/site-packages/numba/core/config.py", line 17, in <module>
    from numba.core import config
  File "/home/t/t541/.local/lib/python3.9/site-packages/numba/core/config.py", line 17, in <module>
    import llvmlite.binding as ll
  File "/home/t/t541/.local/lib/python3.9/site-packages/llvmlite/binding/__init__.py", line 4, in <module>
    import llvmlite.binding as ll
  File "/home/t/t541/.local/lib/python3.9/site-packages/llvmlite/binding/__init__.py", line 4, in <module>
    from .dylib import *
  File "/home/t/t541/.local/lib/python3.9/site-packages/llvmlite/binding/dylib.py", line 36, in <module>
    from .dylib import *
  File "/home/t/t541/.local/lib/python3.9/site-packages/llvmlite/binding/dylib.py", line 36, in <module>
    ffi.lib.LLVMPY_AddSymbol.argtypes = [
  File "/home/t/t541/.local/lib/python3.9/site-packages/llvmlite/binding/ffi.py", line 139, in __getattr__
    ffi.lib.LLVMPY_AddSymbol.argtypes = [
  File "/home/t/t541/.local/lib/python3.9/site-packages/llvmlite/binding/ffi.py", line 139, in __getattr__
    cfn = getattr(self._lib, name)
  File "/home/t/t541/.local/lib/python3.9/site-packages/llvmlite/binding/ffi.py", line 131, in _lib
    cfn = getattr(self._lib, name)
  File "/home/t/t541/.local/lib/python3.9/site-packages/llvmlite/binding/ffi.py", line 131, in _lib
    self._load_lib()
  File "/home/t/t541/.local/lib/python3.9/site-packages/llvmlite/binding/ffi.py", line 125, in _load_lib
    self._load_lib()
  File "/home/t/t541/.local/lib/python3.9/site-packages/llvmlite/binding/ffi.py", line 125, in _load_lib
    raise OSError("Could not find/load shared object file") from e
OSError: Could not find/load shared object file
    raise OSError("Could not find/load shared object file") from e
OSError: Could not find/load shared object file
--------------------------------------------------------------------------
Primary job  terminated normally, but 1 process returned
a non-zero exit code. Per user-direction, the job has been aborted.
--------------------------------------------------------------------------
--------------------------------------------------------------------------
mpiexec detected that one or more processes exited with non-zero status, thus causing
the job to be terminated. The first process to do so was:

  Process name: [[3806,1],1]
  Exit code:    1
--------------------------------------------------------------------------
